<!DOCTYPE html>
<html lang="en">
  <head>
    <meta charset="UTF-8" />
    <meta name="viewport" content="width=device-width, initial-scale=1.0" />
    <title>try/catch 可以异步捕获代码错误吗</title>
  </head>
  <body>
    <h3><span style="color: red;">try...catch不能异步捕获代码错误。</span>在JavaScript中，</h3>
    <h3>setTimeout 是一个异步函数，它的回调函数会在指定的延时后被放入事件队列，</h3>
    <h3>等待当前执行栈清空后才执行。因此，当 setTimeout 的回调函数执行并抛出错误时，</h3>
    <h3>try...catch 已经执行完毕，无法捕捉到异步回调中的错误</h3>

    <script>
      // 所以一下代码会报错
      //   try {
      //     setTimeout(() => {
      //       throw new Error("err");
      //     }, 200);
      //   } catch (err) {
      //     console.log(err);
      //   }

      // try...catch 不能捕捉在 Promise 链中的异步错误
      //   try {
      //     Promise.resolve().then(() => {
      //       throw new Error("err");
      //     });
      //   } catch (err) {
      //     console.log(err);
      //   }
    </script>

    <script>
      new Promise((resolve, reject) => {
        setTimeout(() => {
          try {
            throw new Error("err");
          } catch (err) {
            reject(err);
          }
        }, 200);
      })
        .then(() => {
          // 正常执行时的处理逻辑
        })
        .catch((err) => {
          console.log(err); // 这里会捕捉到错误
        });
    </script>

    <script>
      /*
            在 Promise 中抛出一个错误（例如通过throw语句）会导致 Promise被拒绝（或失败）。
            要正确处理这个错误，需要在 Promise 链中使用 .catch 方法或在一个 async 函数中使用 try...catch
        */
      // 方法一
      Promise.resolve()
        .then(() => {
          throw new Error("err");
        })
        .catch((err) => {
          console.log(err); // 这里会捕捉到错误
        });

      // 方法二
      async function handleError() {
        try {
          await Promise.resolve().then(() => {
            throw new Error("err");
          });
        } catch (err) {
          console.log(err); // 这里会捕捉到错误
        }
      }

      handleError();
    </script>
  </body>
</html>
